Running all tests...
============================= test session starts ==============================
platform linux -- Python 3.12.10, pytest-8.3.5, pluggy-1.6.0 -- /usr/local/bin/python
cachedir: .pytest_cache
rootdir: /app
configfile: tox.ini
plugins: timeout-2.4.0
collecting ... collected 7 items
INTERNALERROR> Traceback (most recent call last):
INTERNALERROR>   File "/usr/local/lib/python3.12/site-packages/_pytest/main.py", line 283, in wrap_session
INTERNALERROR>     session.exitstatus = doit(config, session) or 0
INTERNALERROR>                          ^^^^^^^^^^^^^^^^^^^^^
INTERNALERROR>   File "/usr/local/lib/python3.12/site-packages/_pytest/main.py", line 336, in _main
INTERNALERROR>     config.hook.pytest_collection(session=session)
INTERNALERROR>   File "/usr/local/lib/python3.12/site-packages/pluggy/_hooks.py", line 512, in __call__
INTERNALERROR>     return self._hookexec(self.name, self._hookimpls.copy(), kwargs, firstresult)
INTERNALERROR>            ^^^^^^^^^^^^^^^^^^^^^^^^^^^^^^^^^^^^^^^^^^^^^^^^^^^^^^^^^^^^^^^^^^^^^^
INTERNALERROR>   File "/usr/local/lib/python3.12/site-packages/pluggy/_manager.py", line 120, in _hookexec
INTERNALERROR>     return self._inner_hookexec(hook_name, methods, kwargs, firstresult)
INTERNALERROR>            ^^^^^^^^^^^^^^^^^^^^^^^^^^^^^^^^^^^^^^^^^^^^^^^^^^^^^^^^^^^^^
INTERNALERROR>   File "/usr/local/lib/python3.12/site-packages/pluggy/_callers.py", line 167, in _multicall
INTERNALERROR>     raise exception
INTERNALERROR>   File "/usr/local/lib/python3.12/site-packages/pluggy/_callers.py", line 139, in _multicall
INTERNALERROR>     teardown.throw(exception)
INTERNALERROR>   File "/usr/local/lib/python3.12/site-packages/_pytest/logging.py", line 790, in pytest_collection
INTERNALERROR>     return (yield)
INTERNALERROR>             ^^^^^
INTERNALERROR>   File "/usr/local/lib/python3.12/site-packages/pluggy/_callers.py", line 139, in _multicall
INTERNALERROR>     teardown.throw(exception)
INTERNALERROR>   File "/usr/local/lib/python3.12/site-packages/_pytest/warnings.py", line 121, in pytest_collection
INTERNALERROR>     return (yield)
INTERNALERROR>             ^^^^^
INTERNALERROR>   File "/usr/local/lib/python3.12/site-packages/pluggy/_callers.py", line 139, in _multicall
INTERNALERROR>     teardown.throw(exception)
INTERNALERROR>   File "/usr/local/lib/python3.12/site-packages/_pytest/config/__init__.py", line 1417, in pytest_collection
INTERNALERROR>     return (yield)
INTERNALERROR>             ^^^^^
INTERNALERROR>   File "/usr/local/lib/python3.12/site-packages/pluggy/_callers.py", line 121, in _multicall
INTERNALERROR>     res = hook_impl.function(*args)
INTERNALERROR>           ^^^^^^^^^^^^^^^^^^^^^^^^^
INTERNALERROR>   File "/usr/local/lib/python3.12/site-packages/_pytest/main.py", line 347, in pytest_collection
INTERNALERROR>     session.perform_collect()
INTERNALERROR>   File "/usr/local/lib/python3.12/site-packages/_pytest/main.py", line 809, in perform_collect
INTERNALERROR>     self.items.extend(self.genitems(node))
INTERNALERROR>   File "/usr/local/lib/python3.12/site-packages/_pytest/main.py", line 975, in genitems
INTERNALERROR>     yield from self.genitems(subnode)
INTERNALERROR>   File "/usr/local/lib/python3.12/site-packages/_pytest/main.py", line 975, in genitems
INTERNALERROR>     yield from self.genitems(subnode)
INTERNALERROR>   File "/usr/local/lib/python3.12/site-packages/_pytest/main.py", line 970, in genitems
INTERNALERROR>     rep, duplicate = self._collect_one_node(node, handle_dupes)
INTERNALERROR>                      ^^^^^^^^^^^^^^^^^^^^^^^^^^^^^^^^^^^^^^^^^^
INTERNALERROR>   File "/usr/local/lib/python3.12/site-packages/_pytest/main.py", line 835, in _collect_one_node
INTERNALERROR>     rep = collect_one_node(node)
INTERNALERROR>           ^^^^^^^^^^^^^^^^^^^^^^
INTERNALERROR>   File "/usr/local/lib/python3.12/site-packages/_pytest/runner.py", line 567, in collect_one_node
INTERNALERROR>     rep: CollectReport = ihook.pytest_make_collect_report(collector=collector)
INTERNALERROR>                          ^^^^^^^^^^^^^^^^^^^^^^^^^^^^^^^^^^^^^^^^^^^^^^^^^^^^^
INTERNALERROR>   File "/usr/local/lib/python3.12/site-packages/pluggy/_hooks.py", line 512, in __call__
INTERNALERROR>     return self._hookexec(self.name, self._hookimpls.copy(), kwargs, firstresult)
INTERNALERROR>            ^^^^^^^^^^^^^^^^^^^^^^^^^^^^^^^^^^^^^^^^^^^^^^^^^^^^^^^^^^^^^^^^^^^^^^
INTERNALERROR>   File "/usr/local/lib/python3.12/site-packages/pluggy/_manager.py", line 120, in _hookexec
INTERNALERROR>     return self._inner_hookexec(hook_name, methods, kwargs, firstresult)
INTERNALERROR>            ^^^^^^^^^^^^^^^^^^^^^^^^^^^^^^^^^^^^^^^^^^^^^^^^^^^^^^^^^^^^^
INTERNALERROR>   File "/usr/local/lib/python3.12/site-packages/pluggy/_callers.py", line 167, in _multicall
INTERNALERROR>     raise exception
INTERNALERROR>   File "/usr/local/lib/python3.12/site-packages/pluggy/_callers.py", line 139, in _multicall
INTERNALERROR>     teardown.throw(exception)
INTERNALERROR>   File "/usr/local/lib/python3.12/site-packages/_pytest/capture.py", line 878, in pytest_make_collect_report
INTERNALERROR>     rep = yield
INTERNALERROR>           ^^^^^
INTERNALERROR>   File "/usr/local/lib/python3.12/site-packages/pluggy/_callers.py", line 121, in _multicall
INTERNALERROR>     res = hook_impl.function(*args)
INTERNALERROR>           ^^^^^^^^^^^^^^^^^^^^^^^^^
INTERNALERROR>   File "/usr/local/lib/python3.12/site-packages/_pytest/runner.py", line 391, in pytest_make_collect_report
INTERNALERROR>     call = CallInfo.from_call(
INTERNALERROR>            ^^^^^^^^^^^^^^^^^^^
INTERNALERROR>   File "/usr/local/lib/python3.12/site-packages/_pytest/runner.py", line 341, in from_call
INTERNALERROR>     result: TResult | None = func()
INTERNALERROR>                              ^^^^^^
INTERNALERROR>   File "/usr/local/lib/python3.12/site-packages/_pytest/runner.py", line 389, in collect
INTERNALERROR>     return list(collector.collect())
INTERNALERROR>                 ^^^^^^^^^^^^^^^^^^^
INTERNALERROR>   File "/usr/local/lib/python3.12/site-packages/_pytest/python.py", line 549, in collect
INTERNALERROR>     self._register_setup_module_fixture()
INTERNALERROR>   File "/usr/local/lib/python3.12/site-packages/_pytest/python.py", line 562, in _register_setup_module_fixture
INTERNALERROR>     self.obj, ("setUpModule", "setup_module")
INTERNALERROR>     ^^^^^^^^
INTERNALERROR>   File "/usr/local/lib/python3.12/site-packages/_pytest/python.py", line 284, in obj
INTERNALERROR>     self._obj = obj = self._getobj()
INTERNALERROR>                       ^^^^^^^^^^^^^^
INTERNALERROR>   File "/usr/local/lib/python3.12/site-packages/_pytest/python.py", line 546, in _getobj
INTERNALERROR>     return importtestmodule(self.path, self.config)
INTERNALERROR>            ^^^^^^^^^^^^^^^^^^^^^^^^^^^^^^^^^^^^^^^^
INTERNALERROR>   File "/usr/local/lib/python3.12/site-packages/_pytest/python.py", line 493, in importtestmodule
INTERNALERROR>     mod = import_path(
INTERNALERROR>           ^^^^^^^^^^^^
INTERNALERROR>   File "/usr/local/lib/python3.12/site-packages/_pytest/pathlib.py", line 587, in import_path
INTERNALERROR>     importlib.import_module(module_name)
INTERNALERROR>   File "/usr/local/lib/python3.12/importlib/__init__.py", line 90, in import_module
INTERNALERROR>     return _bootstrap._gcd_import(name[level:], package, level)
INTERNALERROR>            ^^^^^^^^^^^^^^^^^^^^^^^^^^^^^^^^^^^^^^^^^^^^^^^^^^^^
INTERNALERROR>   File "<frozen importlib._bootstrap>", line 1387, in _gcd_import
INTERNALERROR>   File "<frozen importlib._bootstrap>", line 1360, in _find_and_load
INTERNALERROR>   File "<frozen importlib._bootstrap>", line 1331, in _find_and_load_unlocked
INTERNALERROR>   File "<frozen importlib._bootstrap>", line 935, in _load_unlocked
INTERNALERROR>   File "/usr/local/lib/python3.12/site-packages/_pytest/assertion/rewrite.py", line 185, in exec_module
INTERNALERROR>     exec(co, module.__dict__)
INTERNALERROR>   File "/app/generated/nidcpower/setup.py", line 16, in <module>
INTERNALERROR>     setup(
INTERNALERROR>   File "/usr/local/lib/python3.12/site-packages/setuptools/__init__.py", line 115, in setup
INTERNALERROR>     return distutils.core.setup(**attrs)
INTERNALERROR>            ^^^^^^^^^^^^^^^^^^^^^^^^^^^^^
INTERNALERROR>   File "/usr/local/lib/python3.12/site-packages/setuptools/_distutils/core.py", line 173, in setup
INTERNALERROR>     ok = dist.parse_command_line()
INTERNALERROR>          ^^^^^^^^^^^^^^^^^^^^^^^^^
INTERNALERROR>   File "/usr/local/lib/python3.12/site-packages/setuptools/_distutils/dist.py", line 502, in parse_command_line
INTERNALERROR>     args = self._parse_command_opts(parser, args)
INTERNALERROR>            ^^^^^^^^^^^^^^^^^^^^^^^^^^^^^^^^^^^^^^
INTERNALERROR>   File "/usr/local/lib/python3.12/site-packages/setuptools/dist.py", line 1003, in _parse_command_opts
INTERNALERROR>     nargs = _Distribution._parse_command_opts(self, parser, args)
INTERNALERROR>             ^^^^^^^^^^^^^^^^^^^^^^^^^^^^^^^^^^^^^^^^^^^^^^^^^^^^^
INTERNALERROR>   File "/usr/local/lib/python3.12/site-packages/setuptools/_distutils/dist.py", line 554, in _parse_command_opts
INTERNALERROR>     raise SystemExit(f"invalid command name '{command}'")
INTERNALERROR> SystemExit: invalid command name 'generated/'

============================= 3 warnings in 1.00s ==============================
